# java中的异常处理机制:
java中的异常结构定义的父类Throwable,其派生的两个子类别:  
Error:用于标识JRE的错误,该类错误是无法通过程序解决的      
    OutOfMemoryError:堆内存溢出   
    StackOverflowError:栈内存溢出   
Exception:表示程序级别的异常,该类错误是可以通过程序解决的   
注意:  
1. 异常是行为\方法\过程的意外结果
2. 一个方法如果抛出了异常,这个方法就必须声明异常的抛出
3. 异常的声明:在方法上声明方法的意外结果
4. 异常类一般都继承自Excepthion
5. 调用抛出异常的方法,必须处理异常,有两种方案:
    1. 使用try-catch-finally捕获异常
    2. 使用throws关键字直接抛出异常
6. 如果出现异常,异常以后的代码不会再执行(除了finally)

java异常捕获机制的语法:   
```java
try{  
//可能出现异常的代码片段
}catch(XXXException e){
//用来解决问题的代码片段(catch块跟在try块后,用于捕获并解决异常,catch块允许出现多次)
}finally{
//不管是否出现异常,总会执行的代码块
//通常我们会使用finally语句块作为程序的收尾工作
}
```

```java
package day07;
//java异常捕获机制:程序中只能解决Excepthion,不能解决Error
public class ExceptionDemo1 {
	public static void main(String[] args) {
		System.out.println("程序开始了");
		try {
			/*
			 * JVM发现我们需要调用一个null的方法,JVM会创建一个空指针异常的实例
			 * 来描述这里发生的异常,在当前行抛出异常,抛出后JVM会检查我们的代码片段
			 * 查看是否有异常捕获机制,当发现当前代码行没有异常捕获机制,则将该异常实例
			 * 抛出到当前代码所在的方法之外,当异常逐级抛出到main方法之外时,JVM会杀掉
			 * 当前程序,程序退出
			 */
			String str = "a";
			System.out.println(str.length());
			System.out.println(str.charAt(0));
			int i = Integer.parseInt(str);
			System.out.println(i);
			/*
			 * 当上面的代码片段出现了异常,会跳出try语句
			 * 那么try语句块中剩下的代码片段不能被执行
			 */
			System.out.println("内容都执行了");
		} catch (NullPointerException e) {
			System.out.println("出现了空指针异常");
		} catch(StringIndexOutOfBoundsException e) {
			System.out.println("字符串下标越界异常");
		} catch(Exception e) {
			/*
			 * 异常捕获机制的良好习惯:
			 * 在最后一个catch捕获Excepthion,以保证可以捕获程序中出现的其他
			 * 异常,使得程序不会出现闪退现象
			 */
			System.out.println("反正出了个错");
		}
		System.out.println("程序结束了");
	}
}

```

```java
package day07;
/*
 * finally永远会被执行
 * catch中的异常有顺序,异常从小到大,否则会出现编译错误
 * NullpointerException
 * StringIndexOutOfBoundsExceptions
 * ArrayIndexOutOfBoundsExceptions
 * ...都属于RuntimeException-->Exception
 */
public class ExceptionDemo2 {
	public static void main(String[] args) {
		System.out.println(test(null)+","+test("0")+","+test(""));
	}
	public static int test(String str) {
		try {
			return str.charAt(0)-'0';
		} catch (NullPointerException e) {
			return 1;
		} catch(StringIndexOutOfBoundsException e) {
			return 2;
		} catch(RuntimeException e) {
			return 3;
		} catch(Exception e) {
			return 4;
		} finally {
			//final中最后不要书写return语句,因为永远会被执行
//			return 5;
			System.out.println("结束");
		}
	}
}

```

```java
package day07;
/*
 * throw关键字:用于主动抛出异常
 * 通常以下两种情况会主动抛出异常:
 * 1.当前语法片段出现了一个语法错误,这个错误是不满足业务逻辑的情况时,我们会主动
 * 抛出异常
 * 2.当前代码片段出现了一个异常,但是该异常的处理不应该是当前代码片段负责处理时,
 * 我们也需要主动抛出异常
 */
public class ExceptionDemo3 {
	public static void main(String[] args) {
		try {
			Person p = new Person();
			p.setAge(1000);
			System.out.println(p);
		} catch (Exception e) {
			//输出异常出现的堆栈信息
			e.printStackTrace();
			//输出异常出现的原因
			System.out.println(e.getMessage());
		}
		System.out.println("程序结束了");
	}
}
class Person{
	private int age;

	public int getAge() {
		return age;
	}

	public void setAge(int age) {
		if(age<0||age>250) {
			throw new RuntimeException("不是正常人类的年龄");
		}
		this.age = age;
	}

	public String toString() {
		return "我的年龄是:" + age;
	}
}

```
